[{'answer1': '\n\n```json\n{\n  "intentOfThisFunction": "The function is intended to repeatedly attempt verification of data using a delegate within a specified time frame (controlled by a timer). If verification succeeds and \'returnOnSuccess\' is enabled, it exits early. If verification fails, it captures the error and continues retrying until the timer expires, then throws the last captured error (if any).",\n  "faultLocalization": [\n    {\n      "lineNumber": 86,\n      "codeContent": "error = null;",\n      "reason": "Resetting \'error\' to null on a successful verification (when \'returnOnSuccess\' is false) discards previous errors. If the loop continues and a subsequent attempt succeeds, transient failures during the loop are masked, potentially leading to a false positive."\n    },\n    {\n      "lineNumber": 79,\n      "codeContent": "while (timer.isCounting()) {",\n      "reason": "The loop lacks a delay mechanism (e.g., Thread.sleep(), timer.wait(), or backoff). This may cause excessive CPU usage or a tight loop, especially if \'timer.isCounting()\' depends on elapsed time and the loop iterates too quickly."\n    },\n    {\n      "lineNumber": 96,\n      "codeContent": "if (error != null) {",\n      "reason": "The final error check only throws the last captured error. If the last verification attempt succeeds (setting \'error\' to null), previous errors are ignored, potentially hiding intermittent failures that occurred during the loop."\n    },\n    {\n      "lineNumber": 83,\n      "codeContent": "if (returnOnSuccess) {",\n      "reason": "The \'returnOnSuccess\' flag may lead to unintended behavior. When true, it exits immediately on success, but when false, it continues retrying without preserving prior errors, which could conflict with the intended retry logic."\n    },\n    {\n      "lineNumber": 91,\n      "codeContent": "catch (org.mockito.exceptions.verification.junit.ArgumentsAreDifferent e) {",\n      "reason": "This catch block may be unreachable if \'ArgumentsAreDifferent\' is a subclass of \'MockitoAssertionError\' (line 88). If so, this exception would already be caught by the earlier catch block, making this code redundant."\n    }\n  ]\n}\n```'}]